Workbook

Sheet Cover
A1: Project Lumière – LBO model
A2: ARCHIMED Investment Director case study (practice). Fictional company; €m unless stated.
A4: How to use
A5: Change inputs only on the Inputs sheet (and the sensitivity axes on Returns). Every other number is a formula.
A6: Colour code: blue text = hardcoded input · yellow fill = key lever to flex live · black = formula · green = link to another sheet.
A7: Three full LBOs run side by side: LBO_Base (ARCHIMED case), LBO_Mgmt (vendor plan restated), LBO_Down (downside).
A8: Interview levers: entry multiple (Inputs C9), leverage (C28), earn-out (C21), growth and margin flex (C52–C53), exit multiples (D59–F59).
A9: Interest is charged on opening balances, so the model has no circular references and needs no iterative calculation.
A11: Sheet guide
A12: Sheet | B12: What it does
A13: Inputs | B13: Every assumption, with its source in column I
A14: Case_Data | B14: Information-memo data: history, vendor vs. ARCHIMED EBITDA bridge, vendor plan, KPIs
A15: Transaction | B15: Sources and uses, ownership, entry metrics
A16: LBO_Base / LBO_Mgmt / LBO_Down | B16: Revenue and EBITDA build, add-ons, free cash flow, tax, debt, credit stats, returns, equity bridge
A17: Returns | B17: Case comparison, value bridge, bid ladder, IRR and MOIC grids, model checks
A19: Key outputs (live)
A20: Metric | C20: Base | D20: Management | E20: Downside
A21: Entry enterprise value (€m) | C21: =Inputs!C10 -> 540
A22: Entry EV / underwritten EBITDA | C22: =Inputs!C9 -> 13.5
A23: Entry EV / vendor Adjusted EBITDA | C23: =Inputs!C11 -> 12.413793
A24: Total equity invested (€m) | C24: =Transaction!C20 -> 328.2
A25: ARCHIMED equity (€m) | C25: =Transaction!C15 -> 282.2
A26: IRR | C26: =Returns!C18 -> 0.19985379 | D26: =Returns!D18 -> 0.23980895 | E26: =Returns!E18 -> 0.033350564
A27: MOIC | C27: =Returns!C17 -> 2.4868045 | D27: =Returns!D17 -> 2.9293673 | E27: =Returns!E17 -> 1.1782526
A28: All model checks OK (1 = yes) | C28: =Returns!C87 -> 1

Sheet Inputs
A1: Project Lumière – inputs and assumptions
A2: Blue = hardcoded input · yellow fill = key lever to flex · black = formula · green = link to another sheet. €m unless stated.
A4: 1. Transaction and valuation
A5: FY2026E revenue | B5: €m | C5: =Case_Data!G9 -> 150 | I5: Case_Data
A6: FY2026E reported EBITDA (IFRS 16) | B6: €m | C6: =Case_Data!G16 -> 41.9 | I6: Case_Data
A7: FY2026E vendor Adjusted EBITDA | B7: €m | C7: =Case_Data!G23 -> 43.5 | I7: Case_Data: vendor definition
A8: FY2026E underwritten EBITDA (ARCHIMED definition) | B8: €m | C8: =Case_Data!G28 -> 40 | I8: Case_Data: pre-IFRS 16, IVDR costs treated as recurring, standalone costs included
A9: Entry EV / underwritten EBITDA | B9: x | C9: 13.5 | I9: ARCHIMED bid: highest price at which the base case clears 20% IRR / 2.5x MOIC
A10: Entry enterprise value | B10: €m | C10: =C9*C8 -> 540
A11: Implied EV / vendor Adjusted EBITDA | B11: x | C11: =C10/C7 -> 12.413793
A12: Implied EV / FY2026E revenue | B12: x | C12: =C10/C5 -> 3.6
A13: Vendor price expectation | B13: €m | C13: 600 | I13: Case brief: sell-side guidance, cash-free / debt-free
A14: Vendor price / underwritten EBITDA | B14: x | C14: =C13/C8 -> 15
A15: Vendor price / vendor Adjusted EBITDA | B15: x | C15: =C13/C7 -> 13.793103
A16: Transaction costs (% of EV) | B16: % | C16: 0.02 | I16: Case brief: M&A, due diligence, legal, W&I insurance, registration duties
A17: Minimum cash (funded at closing) | B17: €m | C17: 10 | I17: Case brief
A18: Founder rollover | B18: €m | C18: 40 | I18: Case brief: founder reinvests c.€40m alongside ARCHIMED (same instrument strip)
A19: Management rollover | B19: €m | C19: 6 | I19: ARCHIMED proposal: existing managers reinvest part of their 8% stake
A20: MIP: management share of capital gain | B20: % | C20: 0.1 | I20: ARCHIMED proposal: sweet equity worth 10% of the equity gain at exit
A21: Earn-out: maximum payment | B21: €m | C21: 40 | I21: ARCHIMED proposal: bridges the gap to the vendor price only if the plan is delivered
A22: Earn-out: measurement year (organic EBITDA) | B22: year | C22: 2028 | I22: ARCHIMED proposal
A23: Earn-out: payment year | B23: year | C23: 2029 | I23: ARCHIMED proposal
A24: Earn-out: organic EBITDA floor (0% paid) | B24: €m | C24: 50 | I24: Linear payout between floor and cap; base case FY2028 organic EBITDA is c.€49m
A25: Earn-out: organic EBITDA cap (100% paid) | B25: €m | C25: 53.5 | I25: Management plan FY2028 EBITDA on the ARCHIMED definition is c.€54m, so the plan earns 100%
A27: 2. Financing
A28: Unitranche leverage (x underwritten EBITDA) | B28: x | C28: 6 | I28: Case brief: indicative terms, up to 6.0x
A29: Unitranche at closing | B29: €m | C29: =C28*C8 -> 240
A30: Unitranche upfront fee | B30: % | C30: 0.025 | I30: Case brief
A31: Capex and acquisition facility (CAF) commitment | B31: €m | C31: 110 | I31: Case brief
A32: Revolving credit facility (RCF) commitment | B32: €m | C32: 30 | I32: Case brief
A33: Upfront fee on CAF and RCF | B33: % | C33: 0.01 | I33: Case brief
A34: 3-month Euribor (flat) | B34: % | C34: 0.02 | I34: Case brief assumption
A35: Unitranche margin | B35: % | C35: 0.0475 | I35: Case brief
A36: CAF margin | B36: % | C36: 0.0475 | I36: Case brief
A37: RCF margin | B37: % | C37: 0.04 | I37: Case brief
A38: Commitment fee (% of margin, on undrawn amounts) | B38: % | C38: 0.35 | I38: Case brief
A39: Interest income on cash | B39: % | C39: 0.015 | I39: Assumption
A40: Excess cash used to prepay the unitranche | B40: % | C40: 1 | I40: Assumption: voluntary prepayment at par of cash above the minimum
A41: Net leverage covenant (maintenance test) | B41: x | C41: 8.25 | I41: Assumption: set with c.30% EBITDA headroom to closing leverage of 5.75x
A43: 3. Operating cases (organic, ARCHIMED EBITDA definition)
...

Sheet Case_Data
A1: Project Lumière – case data from the information memo
A2: Fictional company. All figures as given in the case brief; €m, financial year to December.
A4: Historical P&L
A5: €m | B5: Unit | C5: FY2022A | D5: FY2023A | E5: FY2024A | F5: FY2025A | G5: FY2026E
A6: Revenue – autoimmunity | B6: €m | C6: 72 | D6: 78 | E6: 84 | F6: 89.9 | G6: 96
A7: Revenue – allergy | B7: €m | C7: 33.5 | D7: 35 | E7: 37 | F7: 39.6 | G7: 42
A8: Revenue – other serology | B8: €m | C8: 10.3 | D8: 10.9 | E8: 11.4 | F8: 11.4 | G8: 12
A9: Total revenue | B9: €m | C9: =SUM(C6:C8) -> 115.8 | D9: =SUM(D6:D8) -> 123.9 | E9: =SUM(E6:E8) -> 132.4 | F9: =SUM(F6:F8) -> 140.9 | G9: =SUM(G6:G8) -> 150
A10: Revenue growth | B10: % | D10: =D9/C9-1 -> 0.069948187 | E10: =E9/D9-1 -> 0.068603713 | F10: =F9/E9-1 -> 0.064199396 | G10: =G9/F9-1 -> 0.064584812
A11: Gross profit | B11: €m | C11: 70.6 | D11: 76 | E11: 81.6 | F11: 87.1 | G11: 93 | I11: Information memo; reagent gross margins improve with the shift to automated CLIA
A12: Gross margin | B12: % | C12: =C11/C9 -> 0.60967185 | D12: =D11/D9 -> 0.6133979 | E12: =E11/E9 -> 0.6163142 | F12: =F11/F9 -> 0.61816891 | G12: =G11/G9 -> 0.62
A13: Sales and marketing | B13: €m | C13: -23.4 | D13: -24.9 | E13: -26.4 | F13: -27.9 | G13: -29.7
A14: R&D (expensed) | B14: €m | C14: -8 | D14: -8.5 | E14: -8.9 | F14: -9.3 | G14: -9.8
A15: G&A | B15: €m | C15: -9.8 | D15: -10.6 | E15: -11 | F15: -11.3 | G15: -11.6
A16: Reported EBITDA (IFRS 16) | B16: €m | C16: =C11+C13+C14+C15 -> 29.4 | D16: =D11+D13+D14+D15 -> 32 | E16: =E11+E13+E14+E15 -> 35.3 | F16: =F11+F13+F14+F15 -> 38.6 | G16: =G11+G13+G14+G15 -> 41.9
A17: Reported EBITDA margin | B17: % | C17: =C16/C9 -> 0.25388601 | D17: =D16/D9 -> 0.2582728 | E17: =E16/E9 -> 0.26661631 | F17: =F16/F9 -> 0.27395316 | G17: =G16/G9 -> 0.27933333
A19: EBITDA bridge: vendor presentation vs. ARCHIMED underwriting
A20: €m | B20: Unit | C20: FY2022A | D20: FY2023A | E20: FY2024A | F20: FY2025A | G20: FY2026E
A21: Reported EBITDA (IFRS 16) | B21: €m | C21: =C16 -> 29.4 | D21: =D16 -> 32 | E21: =E16 -> 35.3 | F21: =F16 -> 38.6 | G21: =G16 -> 41.9
A22: Vendor add-back: IVDR remediation ("one-off") | B22: €m | C22: 0.4 | D22: 0.9 | E22: 1.4 | F22: 1.5 | G22: 1.6 | I22: Vendor adds back IVDR costs every year; 45 assays still to certify by end-2028/2029
A23: Vendor Adjusted EBITDA | B23: €m | C23: =C21+C22 -> 29.8 | D23: =D21+D22 -> 32.9 | E23: =E21+E22 -> 36.7 | F23: =F21+F22 -> 40.1 | G23: =G21+G22 -> 43.5
A24: Vendor Adjusted EBITDA margin | B24: % | C24: =C23/C9 -> 0.25734024 | D24: =D23/D9 -> 0.26553672 | E24: =E23/E9 -> 0.27719033 | F24: =F23/F9 -> 0.28459901 | G24: =G23/G9 -> 0.29
A25: ARCHIMED: reverse IVDR add-back (cost recurs until 2029) | B25: €m | C25: =-C22 -> -0.4 | D25: =-D22 -> -0.9 | E25: =-E22 -> -1.4 | F25: =-F22 -> -1.5 | G25: =-G22 -> -1.6 | I25: ARCHIMED view: a cost incurred five years running is recurring until the transition ends
A26: ARCHIMED: IFRS 16 lease costs (restate to pre-IFRS 16) | B26: €m | C26: -1 | D26: -1.1 | E26: -1.2 | F26: -1.2 | G26: -1.3 | I26: Information memo note: plant, office and car leases; lenders and peers use pre-IFRS 16 EBITDA
A27: ARCHIMED: standalone costs (market-rate CEO, CFO, board) | B27: €m | C27: -0.6 | D27: -0.6 | E27: -0.6 | F27: -0.6 | G27: -0.6 | I27: Information memo note: founder paid €0.4m; replacement team costs c.€0.6m more a year
A28: Underwritten EBITDA (pre-IFRS 16, fully loaded) | B28: €m | C28: =C23+C25+C26+C27 -> 27.8 | D28: =D23+D25+D26+D27 -> 30.3 | E28: =E23+E25+E26+E27 -> 33.5 | F28: =F23+F25+F26+F27 -> 36.8 | G28: =G23+G25+G26+G27 -> 40
A29: Underwritten EBITDA margin | B29: % | C29: =C28/C9 -> 0.24006908 | D29: =D28/D9 -> 0.24455206 | E29: =E28/E9 -> 0.25302115 | F29: =F28/F9 -> 0.26117814 | G29: =G28/G9 -> 0.26666667
A30: Vendor Adjusted minus underwritten EBITDA | B30: €m | C30: =C23-C28 -> 2 | D30: =D23-D28 -> 2.6 | E30: =E23-E28 -> 3.2 | F30: =F23-F28 -> 3.3 | G30: =G23-G28 -> 3.5
A32: Cash flow items
A33: €m | B33: Unit | C33: FY2022A | D33: FY2023A | E33: FY2024A | F33: FY2025A | G33: FY2026E
A34: Capex incl. placed analyzers and capitalised R&D | B34: €m | C34: 6.9 | D34: 7.4 | E34: 7.9 | F34: 8.4 | G34: 8.9
A35: Capex, % of revenue | B35: % | C35: =C34/C9 -> 0.059585492 | D35: =D34/D9 -> 0.059725585 | E35: =E34/E9 -> 0.059667674 | F35: =F34/F9 -> 0.059616749 | G35: =G34/G9 -> 0.059333333
A36: Net working capital | B36: €m | C36: 25 | D36: 27.4 | E36: 29.7 | F36: 31 | G36: 33
A37: Net working capital, % of revenue | B37: % | C37: =C36/C9 -> 0.21588946 | D37: =D36/D9 -> 0.22114609 | E37: =E36/E9 -> 0.22432024 | F37: =F36/F9 -> 0.22001419 | G37: =G36/G9 -> 0.22
A38: Cash conversion: (underwritten EBITDA – capex – ΔNWC) / EBITDA | B38: % | D38: =(D28-D34-(D36-C36))/D28 -> 0.67656766 | E38: =(E28-E34-(E36-D36))/E28 -> 0.69552239 | F38: =(F28-F34-(F36-E36))/F28 -> 0.73641304 | G38: =(G28-G34-(G36-F36))/G28 -> 0.7275
A40: Management business plan (vendor case, no M&A)
A41: €m | B41: Unit | C41: FY2027 | D41: FY2028 | E41: FY2029 | F41: FY2030 | G41: FY2031
A42: Revenue growth | B42: % | C42: 0.1 | D42: 0.11 | E42: 0.115 | F42: 0.115 | G42: 0.11 | I42: Drivers: US push (30 new FDA submissions), next-gen CLIA analyzer in 2028, price, automation
A43: Revenue | B43: €m | C43: =$G$9*(1+C42) -> 165 | D43: =C43*(1+D42) -> 183.15 | E43: =D43*(1+E42) -> 204.21225 | F43: =E43*(1+F42) -> 227.69666 | G43: =F43*(1+G42) -> 252.74329
A44: Adjusted EBITDA margin (vendor definition) | B44: % | C44: 0.303 | D44: 0.318 | E44: 0.333 | F44: 0.343 | G44: 0.348
...

Sheet Transaction
A1: Project Lumière – sources and uses at closing (31 December 2026)
A2: €m unless stated. All cells are formulas driven by the Inputs sheet.
A4: Uses | C4: €m | D4: % of total
A5: Enterprise value (cash-free, debt-free) | B5: €m | C5: =Inputs!C10 -> 540 | D5: =C5/$C$9 -> 0.95036959
A6: Transaction costs (M&A, due diligence, legal, W&I) | B6: €m | C6: =Inputs!C16*C5 -> 10.8 | D6: =C6/$C$9 -> 0.019007392
A7: Financing fees (unitranche, CAF and RCF upfront fees) | B7: €m | C7: =Inputs!C29*Inputs!C30+(Inputs!C31+Inputs!C32)*Inputs!C33 -> 7.4 | D7: =C7/$C$9 -> 0.013023583
A8: Cash funded to the balance sheet | B8: €m | C8: =Inputs!C17 -> 10 | D8: =C8/$C$9 -> 0.017599437
A9: Total uses | B9: €m | C9: =SUM(C5:C8) -> 568.2 | D9: =SUM(D5:D8) -> 1
A11: Sources
A12: Unitranche | B12: €m | C12: =Inputs!C29 -> 240 | D12: =C12/$C$16 -> 0.42238648
A13: Founder rollover | B13: €m | C13: =Inputs!C18 -> 40 | D13: =C13/$C$16 -> 0.070397747
A14: Management rollover | B14: €m | C14: =Inputs!C19 -> 6 | D14: =C14/$C$16 -> 0.010559662
A15: ARCHIMED equity (MED Platform II and co-investors) | B15: €m | C15: =C9-C12-C13-C14 -> 282.2 | D15: =C15/$C$16 -> 0.49665611 | E15: Plug: total uses less debt and rollovers
A16: Total sources | B16: €m | C16: =SUM(C12:C15) -> 568.2 | D16: =SUM(D12:D15) -> 1
A17: Check: sources minus uses (should be 0) | C17: =C16-C9 -> 0
A19: Equity and ownership (before MIP dilution)
A20: Total equity invested | B20: €m | C20: =C13+C14+C15 -> 328.2 | D20: =SUM(D21:D23) -> 1
A21: ARCHIMED | B21: €m | C21: =C15 -> 282.2 | D21: =C21/$C$20 -> 0.85984156 | E21: All holders invest in the same strip; management MIP comes on top (see Inputs C20)
A22: Founder | B22: €m | C22: =C13 -> 40 | D22: =C22/$C$20 -> 0.1218769
A23: Management | B23: €m | C23: =C14 -> 6 | D23: =C23/$C$20 -> 0.018281536
A25: Entry metrics
A26: EV / underwritten FY2026E EBITDA | B26: x | C26: =C5/Inputs!C8 -> 13.5
A27: EV / vendor Adjusted FY2026E EBITDA | B27: x | C27: =C5/Inputs!C7 -> 12.413793
A28: EV / FY2026E revenue | B28: x | C28: =C5/Inputs!C5 -> 3.6
A29: Unitranche / underwritten EBITDA | B29: x | C29: =C12/Inputs!C8 -> 6
A30: Net debt at closing / underwritten EBITDA | B30: x | C30: =(C12-C8)/Inputs!C8 -> 5.75
A31: Equity / total sources | B31: % | C31: =C20/C16 -> 0.57761352
A32: Unitranche / EV (loan-to-value) | B32: % | C32: =C12/C5 -> 0.44444444
A33: Total fees / EV | B33: % | C33: =(C6+C7)/C5 -> 0.033703704

Sheet LBO_Base
A1: Project Lumière – LBO model: Base (ARCHIMED) case
A2: €m unless stated · financial year to December · closing 31 December 2026 · exit 31 December 2031
A3: Case index (1 = Base, 2 = Management, 3 = Downside) | C3: 1
A5: €m | B5: Unit | C5: FY2026E | D5: FY2027 | E5: FY2028 | F5: FY2029 | G5: FY2030 | H5: FY2031
A6: Years from closing | C6: 0 | D6: =C6+1 -> 1 | E6: =D6+1 -> 2 | F6: =E6+1 -> 3 | G6: =F6+1 -> 4 | H6: =G6+1 -> 5
A7: Financial year | C7: 2026 | D7: =C7+1 -> 2027 | E7: =D7+1 -> 2028 | F7: =E7+1 -> 2029 | G7: =F7+1 -> 2030 | H7: =G7+1 -> 2031
A9: Revenue
A10: Organic revenue growth | B10: % | D10: =INDEX(Inputs!D$45:D$47,$C$3)+Inputs!$C$52 -> 0.075 | E10: =INDEX(Inputs!E$45:E$47,$C$3)+Inputs!$C$52 -> 0.08 | F10: =INDEX(Inputs!F$45:F$47,$C$3)+Inputs!$C$52 -> 0.085 | G10: =INDEX(Inputs!G$45:G$47,$C$3)+Inputs!$C$52 -> 0.085 | H10: =INDEX(Inputs!H$45:H$47,$C$3)+Inputs!$C$52 -> 0.08 | I10: Inputs rows 45–47 picked by case index, plus the flex delta
A11: Organic revenue | B11: €m | C11: =Inputs!$C$5 -> 150 | D11: =C11*(1+D10) -> 161.25 | E11: =D11*(1+E10) -> 174.15 | F11: =E11*(1+F10) -> 188.95275 | G11: =F11*(1+G10) -> 205.01373 | H11: =G11*(1+H10) -> 221.41483
A12: Add-on A revenue (Germany) | B12: €m | C12: 0 | D12: =IF(AND(INDEX(Inputs!$D$57:$F$57,$C$3)=1,D$7>=Inputs!$D$74),Inputs!$D$75*(1+Inputs!$D$76)^(D$7-Inputs!$D$74+1),0) -> 0 | E12: =IF(AND(INDEX(Inputs!$D$57:$F$57,$C$3)=1,E$7>=Inputs!$D$74),Inputs!$D$75*(1+Inputs!$D$76)^(E$7-Inputs!$D$74+1),0) -> 29.12 | F12: =IF(AND(INDEX(Inputs!$D$57:$F$57,$C$3)=1,F$7>=Inputs!$D$74),Inputs!$D$75*(1+Inputs!$D$76)^(F$7-Inputs!$D$74+1),0) -> 30.2848 | G12: =IF(AND(INDEX(Inputs!$D$57:$F$57,$C$3)=1,G$7>=Inputs!$D$74),Inputs!$D$75*(1+Inputs!$D$76)^(G$7-Inputs!$D$74+1),0) -> 31.496192 | H12: =IF(AND(INDEX(Inputs!$D$57:$F$57,$C$3)=1,H$7>=Inputs!$D$74),Inputs!$D$75*(1+Inputs!$D$76)^(H$7-Inputs!$D$74+1),0) -> 32.75604 | I12: Consolidated from 1 January of the acquisition year
A13: Add-on B revenue (US) | B13: €m | C13: 0 | D13: =IF(AND(INDEX(Inputs!$D$58:$F$58,$C$3)=1,D$7>=Inputs!$E$74),Inputs!$E$75*(1+Inputs!$E$76)^(D$7-Inputs!$E$74+1),0) -> 0 | E13: =IF(AND(INDEX(Inputs!$D$58:$F$58,$C$3)=1,E$7>=Inputs!$E$74),Inputs!$E$75*(1+Inputs!$E$76)^(E$7-Inputs!$E$74+1),0) -> 0 | F13: =IF(AND(INDEX(Inputs!$D$58:$F$58,$C$3)=1,F$7>=Inputs!$E$74),Inputs!$E$75*(1+Inputs!$E$76)^(F$7-Inputs!$E$74+1),0) -> 20.16 | G13: =IF(AND(INDEX(Inputs!$D$58:$F$58,$C$3)=1,G$7>=Inputs!$E$74),Inputs!$E$75*(1+Inputs!$E$76)^(G$7-Inputs!$E$74+1),0) -> 22.5792 | H13: =IF(AND(INDEX(Inputs!$D$58:$F$58,$C$3)=1,H$7>=Inputs!$E$74),Inputs!$E$75*(1+Inputs!$E$76)^(H$7-Inputs!$E$74+1),0) -> 25.288704
A14: Total revenue | B14: €m | C14: =SUM(C11:C13) -> 150 | D14: =SUM(D11:D13) -> 161.25 | E14: =SUM(E11:E13) -> 203.27 | F14: =SUM(F11:F13) -> 239.39755 | G14: =SUM(G11:G13) -> 259.08913 | H14: =SUM(H11:H13) -> 279.45958
A15: Total revenue growth | B15: % | D15: =D14/C14-1 -> 0.075 | E15: =E14/D14-1 -> 0.26058915 | F15: =F14/E14-1 -> 0.17773183 | G15: =G14/F14-1 -> 0.082254709 | H15: =H14/G14-1 -> 0.078623332
A17: EBITDA (ARCHIMED definition: pre-IFRS 16, fully loaded)
A18: Organic EBITDA margin | B18: % | C18: =C19/C11 -> 0.26666667 | D18: =INDEX(Inputs!D$48:D$50,$C$3)+Inputs!$C$53 -> 0.275 | E18: =INDEX(Inputs!E$48:E$50,$C$3)+Inputs!$C$53 -> 0.284 | F18: =INDEX(Inputs!F$48:F$50,$C$3)+Inputs!$C$53 -> 0.293 | G18: =INDEX(Inputs!G$48:G$50,$C$3)+Inputs!$C$53 -> 0.301 | H18: =INDEX(Inputs!H$48:H$50,$C$3)+Inputs!$C$53 -> 0.308
A19: Organic EBITDA | B19: €m | C19: =Inputs!$C$8 -> 40 | D19: =D11*D18 -> 44.34375 | E19: =E11*E18 -> 49.4586 | F19: =F11*F18 -> 55.363156 | G19: =G11*G18 -> 61.709134 | H19: =H11*H18 -> 68.195768
A20: Add-on A EBITDA (standalone) | B20: €m | C20: 0 | D20: =D12*Inputs!$D$77 -> 0 | E20: =E12*Inputs!$D$77 -> 6.4064 | F20: =F12*Inputs!$D$77 -> 6.662656 | G20: =G12*Inputs!$D$77 -> 6.9291622 | H20: =H12*Inputs!$D$77 -> 7.2063287
A21: Add-on A cost synergies | B21: €m | C21: 0 | D21: =IF(D12>0,Inputs!$D$81*IF(D$7-Inputs!$D$74=0,Inputs!$D$82,IF(D$7-Inputs!$D$74=1,Inputs!$D$83,Inputs!$D$84)),0) -> 0 | E21: =IF(E12>0,Inputs!$D$81*IF(E$7-Inputs!$D$74=0,Inputs!$D$82,IF(E$7-Inputs!$D$74=1,Inputs!$D$83,Inputs!$D$84)),0) -> 0.45 | F21: =IF(F12>0,Inputs!$D$81*IF(F$7-Inputs!$D$74=0,Inputs!$D$82,IF(F$7-Inputs!$D$74=1,Inputs!$D$83,Inputs!$D$84)),0) -> 1.35 | G21: =IF(G12>0,Inputs!$D$81*IF(G$7-Inputs!$D$74=0,Inputs!$D$82,IF(G$7-Inputs!$D$74=1,Inputs!$D$83,Inputs!$D$84)),0) -> 1.8 | H21: =IF(H12>0,Inputs!$D$81*IF(H$7-Inputs!$D$74=0,Inputs!$D$82,IF(H$7-Inputs!$D$74=1,Inputs!$D$83,Inputs!$D$84)),0) -> 1.8
A22: Add-on B EBITDA (standalone) | B22: €m | C22: 0 | D22: =D13*Inputs!$E$77 -> 0 | E22: =E13*Inputs!$E$77 -> 0 | F22: =F13*Inputs!$E$77 -> 4.032 | G22: =G13*Inputs!$E$77 -> 4.51584 | H22: =H13*Inputs!$E$77 -> 5.0577408
A23: Add-on B cost synergies | B23: €m | C23: 0 | D23: =IF(D13>0,Inputs!$E$81*IF(D$7-Inputs!$E$74=0,Inputs!$E$82,IF(D$7-Inputs!$E$74=1,Inputs!$E$83,Inputs!$E$84)),0) -> 0 | E23: =IF(E13>0,Inputs!$E$81*IF(E$7-Inputs!$E$74=0,Inputs!$E$82,IF(E$7-Inputs!$E$74=1,Inputs!$E$83,Inputs!$E$84)),0) -> 0 | F23: =IF(F13>0,Inputs!$E$81*IF(F$7-Inputs!$E$74=0,Inputs!$E$82,IF(F$7-Inputs!$E$74=1,Inputs!$E$83,Inputs!$E$84)),0) -> 0.25 | G23: =IF(G13>0,Inputs!$E$81*IF(G$7-Inputs!$E$74=0,Inputs!$E$82,IF(G$7-Inputs!$E$74=1,Inputs!$E$83,Inputs!$E$84)),0) -> 0.5 | H23: =IF(H13>0,Inputs!$E$81*IF(H$7-Inputs!$E$74=0,Inputs!$E$82,IF(H$7-Inputs!$E$74=1,Inputs!$E$83,Inputs!$E$84)),0) -> 0.5
A24: Total EBITDA | B24: €m | C24: =SUM(C19:C23) -> 40 | D24: =SUM(D19:D23) -> 44.34375 | E24: =SUM(E19:E23) -> 56.315 | F24: =SUM(F19:F23) -> 67.657812 | G24: =SUM(G19:G23) -> 75.454136 | H24: =SUM(H19:H23) -> 82.759838
A25: EBITDA margin | B25: % | C25: =C24/C14 -> 0.26666667 | D25: =D24/D14 -> 0.275 | E25: =E24/E14 -> 0.27704531 | F25: =F24/F14 -> 0.28261698 | G25: =G24/G14 -> 0.29122849 | H25: =H24/H14 -> 0.29614243
A26: EBITDA growth | B26: % | D26: =D24/C24-1 -> 0.10859375 | E26: =E24/D24-1 -> 0.26996476 | F26: =F24/E24-1 -> 0.20141724 | G26: =G24/F24-1 -> 0.1152317 | H26: =H24/G24-1 -> 0.09682308
A28: Free cash flow
A29: EBITDA | B29: €m | D29: =D24 -> 44.34375 | E29: =E24 -> 56.315 | F29: =F24 -> 67.657812 | G29: =G24 -> 75.454136 | H29: =H24 -> 82.759838
A30: One-off integration costs | B30: €m | D30: =-(IF(AND(INDEX(Inputs!$D$57:$F$57,$C$3)=1,D$7=Inputs!$D$74),Inputs!$D$80,0)+IF(AND(INDEX(Inputs!$D$58:$F$58,$C$3)=1,D$7=Inputs!$E$74),Inputs!$E$80,0)) -> 0 | E30: =-(IF(AND(INDEX(Inputs!$D$57:$F$57,$C$3)=1,E$7=Inputs!$D$74),Inputs!$D$80,0)+IF(AND(INDEX(Inputs!$D$58:$F$58,$C$3)=1,E$7=Inputs!$E$74),Inputs!$E$80,0)) -> -2.5 | F30: =-(IF(AND(INDEX(Inputs!$D$57:$F$57,$C$3)=1,F$7=Inputs!$D$74),Inputs!$D$80,0)+IF(AND(INDEX(Inputs!$D$58:$F$58,$C$3)=1,F$7=Inputs!$E$74),Inputs!$E$80,0)) -> -1.5 | G30: =-(IF(AND(INDEX(Inputs!$D$57:$F$57,$C$3)=1,G$7=Inputs!$D$74),Inputs!$D$80,0)+IF(AND(INDEX(Inputs!$D$58:$F$58,$C$3)=1,G$7=Inputs!$E$74),Inputs!$E$80,0)) -> 0 | H30: =-(IF(AND(INDEX(Inputs!$D$57:$F$57,$C$3)=1,H$7=Inputs!$D$74),Inputs!$D$80,0)+IF(AND(INDEX(Inputs!$D$58:$F$58,$C$3)=1,H$7=Inputs!$E$74),Inputs!$E$80,0)) -> 0
A31: Maintenance and placed-analyzer capex | B31: €m | D31: =-D14*Inputs!$C$63 -> -6.45 | E31: =-E14*Inputs!$C$63 -> -8.1308 | F31: =-F14*Inputs!$C$63 -> -9.575902 | G31: =-G14*Inputs!$C$63 -> -10.363565 | H31: =-H14*Inputs!$C$63 -> -11.178383
A32: Capitalised R&D | B32: €m | D32: =-D14*Inputs!$C$64 -> -2.41875 | E32: =-E14*Inputs!$C$64 -> -3.04905 | F32: =-F14*Inputs!$C$64 -> -3.5909633 | G32: =-G14*Inputs!$C$64 -> -3.8863369 | H32: =-H14*Inputs!$C$64 -> -4.1918936
A33: Growth capex | B33: €m | D33: =-Inputs!D$65 -> -5 | E33: =-Inputs!E$65 -> -4 | F33: =-Inputs!F$65 -> -2 | G33: =-Inputs!G$65 -> 0 | H33: =-Inputs!H$65 -> 0
A34: Change in net working capital | B34: €m | D34: =-(D57-C57-D58) -> -2.475 | E34: =-(E57-D57-E58) -> -3.0844 | F34: =-(F57-E57-F58) -> -3.988061 | G34: =-(G57-F57-G58) -> -4.3321467 | H34: =-(H57-G57-H58) -> -4.4814991 | I34: Excludes the working capital bought with add-ons (paid for in the purchase price)
A35: Cash taxes | B35: €m | D35: =-D54 -> -5.7445312 | E35: =-E54 -> -6.68925 | F35: =-F54 -> -8.4726477 | G35: =-G54 -> -9.9658597 | H35: =-H54 -> -10.989727
A36: Net interest expense | B36: €m | D36: =-D86 -> -18.29875 | E36: =-E86 -> -20.614005 | F36: =-F86 -> -21.943744 | G36: =-G86 -> -20.824156 | H36: =-H86 -> -19.063616
A37: Free cash flow | B37: €m | D37: =SUM(D29:D36) -> 3.9567187 | E37: =SUM(E29:E36) -> 8.2474949 | F37: =SUM(F29:F36) -> 16.586494 | G37: =SUM(G29:G36) -> 26.082072 | H37: =SUM(H29:H36) -> 32.854719
A38: Earn-out paid to the vendor | B38: €m | D38: =-IF(D$7=Inputs!$C$23,$C$137,0) -> 0 | E38: =-IF(E$7=Inputs!$C$23,$C$137,0) -> 0 | F38: =-IF(F$7=Inputs!$C$23,$C$137,0) -> 0 | G38: =-IF(G$7=Inputs!$C$23,$C$137,0) -> 0 | H38: =-IF(H$7=Inputs!$C$23,$C$137,0) -> 0 | I38: Paid by the company in the payment year; reduces debt paydown
A39: Add-on acquisitions incl. deal costs | B39: €m | D39: =-(IF(AND(INDEX(Inputs!$D$57:$F$57,$C$3)=1,D$7=Inputs!$D$74),Inputs!$D$86,0)+IF(AND(INDEX(Inputs!$D$58:$F$58,$C$3)=1,D$7=Inputs!$E$74),Inputs!$E$86,0)) -> 0 | E39: =-(IF(AND(INDEX(Inputs!$D$57:$F$57,$C$3)=1,E$7=Inputs!$D$74),Inputs!$D$86,0)+IF(AND(INDEX(Inputs!$D$58:$F$58,$C$3)=1,E$7=Inputs!$E$74),Inputs!$E$86,0)) -> -50.7584 | F39: =-(IF(AND(INDEX(Inputs!$D$57:$F$57,$C$3)=1,F$7=Inputs!$D$74),Inputs!$D$86,0)+IF(AND(INDEX(Inputs!$D$58:$F$58,$C$3)=1,F$7=Inputs!$E$74),Inputs!$E$86,0)) -> -37.08 | G39: =-(IF(AND(INDEX(Inputs!$D$57:$F$57,$C$3)=1,G$7=Inputs!$D$74),Inputs!$D$86,0)+IF(AND(INDEX(Inputs!$D$58:$F$58,$C$3)=1,G$7=Inputs!$E$74),Inputs!$E$86,0)) -> 0 | H39: =-(IF(AND(INDEX(Inputs!$D$57:$F$57,$C$3)=1,H$7=Inputs!$D$74),Inputs!$D$86,0)+IF(AND(INDEX(Inputs!$D$58:$F$58,$C$3)=1,H$7=Inputs!$E$74),Inputs!$E$86,0)) -> 0
A40: Cash flow before debt movements | B40: €m | D40: =D37+D38+D39 -> 3.9567187 | E40: =E37+E38+E39 -> -42.510905 | F40: =F37+F38+F39 -> -20.493506 | G40: =G37+G38+G39 -> 26.082072 | H40: =H37+H38+H39 -> 32.854719
A41: Cash conversion: (EBITDA – capex – ΔNWC) / EBITDA | B41: % | D41: =(D29+D31+D32+D33+D34)/D29 -> 0.63143058 | E41: =(E29+E31+E32+E33+E34)/E29 -> 0.675677 | F41: =(F29+F31+F32+F33+F34)/F29 -> 0.71688522 | G41: =(G29+G31+G32+G33+G34)/G29 -> 0.75373055 | H41: =(H29+H31+H32+H33+H34)/H29 -> 0.7601279
A43: Corporate tax (French interest cap)
A44: EBITDA | B44: €m | D44: =D24 -> 44.34375 | E44: =E24 -> 56.315 | F44: =F24 -> 67.657812 | G44: =G24 -> 75.454136 | H44: =H24 -> 82.759838
A45: One-off integration costs | B45: €m | D45: =D30 -> 0 | E45: =E30 -> -2.5 | F45: =F30 -> -1.5 | G45: =G30 -> 0 | H45: =H30 -> 0
...

Sheet LBO_Mgmt
A1: Project Lumière – LBO model: Management case
A2: €m unless stated · financial year to December · closing 31 December 2026 · exit 31 December 2031
A3: Case index (1 = Base, 2 = Management, 3 = Downside) | C3: 2
A5: €m | B5: Unit | C5: FY2026E | D5: FY2027 | E5: FY2028 | F5: FY2029 | G5: FY2030 | H5: FY2031
A6: Years from closing | C6: 0 | D6: =C6+1 -> 1 | E6: =D6+1 -> 2 | F6: =E6+1 -> 3 | G6: =F6+1 -> 4 | H6: =G6+1 -> 5
A7: Financial year | C7: 2026 | D7: =C7+1 -> 2027 | E7: =D7+1 -> 2028 | F7: =E7+1 -> 2029 | G7: =F7+1 -> 2030 | H7: =G7+1 -> 2031
A9: Revenue
A10: Organic revenue growth | B10: % | D10: =INDEX(Inputs!D$45:D$47,$C$3)+Inputs!$C$52 -> 0.1 | E10: =INDEX(Inputs!E$45:E$47,$C$3)+Inputs!$C$52 -> 0.11 | F10: =INDEX(Inputs!F$45:F$47,$C$3)+Inputs!$C$52 -> 0.115 | G10: =INDEX(Inputs!G$45:G$47,$C$3)+Inputs!$C$52 -> 0.115 | H10: =INDEX(Inputs!H$45:H$47,$C$3)+Inputs!$C$52 -> 0.11 | I10: Inputs rows 45–47 picked by case index, plus the flex delta
A11: Organic revenue | B11: €m | C11: =Inputs!$C$5 -> 150 | D11: =C11*(1+D10) -> 165 | E11: =D11*(1+E10) -> 183.15 | F11: =E11*(1+F10) -> 204.21225 | G11: =F11*(1+G10) -> 227.69666 | H11: =G11*(1+H10) -> 252.74329
A12: Add-on A revenue (Germany) | B12: €m | C12: 0 | D12: =IF(AND(INDEX(Inputs!$D$57:$F$57,$C$3)=1,D$7>=Inputs!$D$74),Inputs!$D$75*(1+Inputs!$D$76)^(D$7-Inputs!$D$74+1),0) -> 0 | E12: =IF(AND(INDEX(Inputs!$D$57:$F$57,$C$3)=1,E$7>=Inputs!$D$74),Inputs!$D$75*(1+Inputs!$D$76)^(E$7-Inputs!$D$74+1),0) -> 29.12 | F12: =IF(AND(INDEX(Inputs!$D$57:$F$57,$C$3)=1,F$7>=Inputs!$D$74),Inputs!$D$75*(1+Inputs!$D$76)^(F$7-Inputs!$D$74+1),0) -> 30.2848 | G12: =IF(AND(INDEX(Inputs!$D$57:$F$57,$C$3)=1,G$7>=Inputs!$D$74),Inputs!$D$75*(1+Inputs!$D$76)^(G$7-Inputs!$D$74+1),0) -> 31.496192 | H12: =IF(AND(INDEX(Inputs!$D$57:$F$57,$C$3)=1,H$7>=Inputs!$D$74),Inputs!$D$75*(1+Inputs!$D$76)^(H$7-Inputs!$D$74+1),0) -> 32.75604 | I12: Consolidated from 1 January of the acquisition year
A13: Add-on B revenue (US) | B13: €m | C13: 0 | D13: =IF(AND(INDEX(Inputs!$D$58:$F$58,$C$3)=1,D$7>=Inputs!$E$74),Inputs!$E$75*(1+Inputs!$E$76)^(D$7-Inputs!$E$74+1),0) -> 0 | E13: =IF(AND(INDEX(Inputs!$D$58:$F$58,$C$3)=1,E$7>=Inputs!$E$74),Inputs!$E$75*(1+Inputs!$E$76)^(E$7-Inputs!$E$74+1),0) -> 0 | F13: =IF(AND(INDEX(Inputs!$D$58:$F$58,$C$3)=1,F$7>=Inputs!$E$74),Inputs!$E$75*(1+Inputs!$E$76)^(F$7-Inputs!$E$74+1),0) -> 20.16 | G13: =IF(AND(INDEX(Inputs!$D$58:$F$58,$C$3)=1,G$7>=Inputs!$E$74),Inputs!$E$75*(1+Inputs!$E$76)^(G$7-Inputs!$E$74+1),0) -> 22.5792 | H13: =IF(AND(INDEX(Inputs!$D$58:$F$58,$C$3)=1,H$7>=Inputs!$E$74),Inputs!$E$75*(1+Inputs!$E$76)^(H$7-Inputs!$E$74+1),0) -> 25.288704
A14: Total revenue | B14: €m | C14: =SUM(C11:C13) -> 150 | D14: =SUM(D11:D13) -> 165 | E14: =SUM(E11:E13) -> 212.27 | F14: =SUM(F11:F13) -> 254.65705 | G14: =SUM(G11:G13) -> 281.77205 | H14: =SUM(H11:H13) -> 310.78803
A15: Total revenue growth | B15: % | D15: =D14/C14-1 -> 0.1 | E15: =E14/D14-1 -> 0.28648485 | F15: =F14/E14-1 -> 0.1996846 | G15: =G14/F14-1 -> 0.10647654 | H15: =H14/G14-1 -> 0.1029768
A17: EBITDA (ARCHIMED definition: pre-IFRS 16, fully loaded)
A18: Organic EBITDA margin | B18: % | C18: =C19/C11 -> 0.26666667 | D18: =INDEX(Inputs!D$48:D$50,$C$3)+Inputs!$C$53 -> 0.27966667 | E18: =INDEX(Inputs!E$48:E$50,$C$3)+Inputs!$C$53 -> 0.29466667 | F18: =INDEX(Inputs!F$48:F$50,$C$3)+Inputs!$C$53 -> 0.30966667 | G18: =INDEX(Inputs!G$48:G$50,$C$3)+Inputs!$C$53 -> 0.31966667 | H18: =INDEX(Inputs!H$48:H$50,$C$3)+Inputs!$C$53 -> 0.32466667
A19: Organic EBITDA | B19: €m | C19: =Inputs!$C$8 -> 40 | D19: =D11*D18 -> 46.145 | E19: =E11*E18 -> 53.9682 | F19: =F11*F18 -> 63.237727 | G19: =G11*G18 -> 72.787032 | H19: =H11*H18 -> 82.057322
A20: Add-on A EBITDA (standalone) | B20: €m | C20: 0 | D20: =D12*Inputs!$D$77 -> 0 | E20: =E12*Inputs!$D$77 -> 6.4064 | F20: =F12*Inputs!$D$77 -> 6.662656 | G20: =G12*Inputs!$D$77 -> 6.9291622 | H20: =H12*Inputs!$D$77 -> 7.2063287
A21: Add-on A cost synergies | B21: €m | C21: 0 | D21: =IF(D12>0,Inputs!$D$81*IF(D$7-Inputs!$D$74=0,Inputs!$D$82,IF(D$7-Inputs!$D$74=1,Inputs!$D$83,Inputs!$D$84)),0) -> 0 | E21: =IF(E12>0,Inputs!$D$81*IF(E$7-Inputs!$D$74=0,Inputs!$D$82,IF(E$7-Inputs!$D$74=1,Inputs!$D$83,Inputs!$D$84)),0) -> 0.45 | F21: =IF(F12>0,Inputs!$D$81*IF(F$7-Inputs!$D$74=0,Inputs!$D$82,IF(F$7-Inputs!$D$74=1,Inputs!$D$83,Inputs!$D$84)),0) -> 1.35 | G21: =IF(G12>0,Inputs!$D$81*IF(G$7-Inputs!$D$74=0,Inputs!$D$82,IF(G$7-Inputs!$D$74=1,Inputs!$D$83,Inputs!$D$84)),0) -> 1.8 | H21: =IF(H12>0,Inputs!$D$81*IF(H$7-Inputs!$D$74=0,Inputs!$D$82,IF(H$7-Inputs!$D$74=1,Inputs!$D$83,Inputs!$D$84)),0) -> 1.8
A22: Add-on B EBITDA (standalone) | B22: €m | C22: 0 | D22: =D13*Inputs!$E$77 -> 0 | E22: =E13*Inputs!$E$77 -> 0 | F22: =F13*Inputs!$E$77 -> 4.032 | G22: =G13*Inputs!$E$77 -> 4.51584 | H22: =H13*Inputs!$E$77 -> 5.0577408
A23: Add-on B cost synergies | B23: €m | C23: 0 | D23: =IF(D13>0,Inputs!$E$81*IF(D$7-Inputs!$E$74=0,Inputs!$E$82,IF(D$7-Inputs!$E$74=1,Inputs!$E$83,Inputs!$E$84)),0) -> 0 | E23: =IF(E13>0,Inputs!$E$81*IF(E$7-Inputs!$E$74=0,Inputs!$E$82,IF(E$7-Inputs!$E$74=1,Inputs!$E$83,Inputs!$E$84)),0) -> 0 | F23: =IF(F13>0,Inputs!$E$81*IF(F$7-Inputs!$E$74=0,Inputs!$E$82,IF(F$7-Inputs!$E$74=1,Inputs!$E$83,Inputs!$E$84)),0) -> 0.25 | G23: =IF(G13>0,Inputs!$E$81*IF(G$7-Inputs!$E$74=0,Inputs!$E$82,IF(G$7-Inputs!$E$74=1,Inputs!$E$83,Inputs!$E$84)),0) -> 0.5 | H23: =IF(H13>0,Inputs!$E$81*IF(H$7-Inputs!$E$74=0,Inputs!$E$82,IF(H$7-Inputs!$E$74=1,Inputs!$E$83,Inputs!$E$84)),0) -> 0.5
A24: Total EBITDA | B24: €m | C24: =SUM(C19:C23) -> 40 | D24: =SUM(D19:D23) -> 46.145 | E24: =SUM(E19:E23) -> 60.8246 | F24: =SUM(F19:F23) -> 75.532383 | G24: =SUM(G19:G23) -> 86.532034 | H24: =SUM(H19:H23) -> 96.621391
A25: EBITDA margin | B25: % | C25: =C24/C14 -> 0.26666667 | D25: =D24/D14 -> 0.27966667 | E25: =E24/E14 -> 0.28654355 | F25: =F24/F14 -> 0.29660433 | G25: =G24/G14 -> 0.30709942 | H25: =H24/H14 -> 0.31089161
A26: EBITDA growth | B26: % | D26: =D24/C24-1 -> 0.153625 | E26: =E24/D24-1 -> 0.31811897 | F26: =F24/E24-1 -> 0.24180649 | G26: =G24/F24-1 -> 0.14562829 | H26: =H24/G24-1 -> 0.11659679
A28: Free cash flow
A29: EBITDA | B29: €m | D29: =D24 -> 46.145 | E29: =E24 -> 60.8246 | F29: =F24 -> 75.532383 | G29: =G24 -> 86.532034 | H29: =H24 -> 96.621391
A30: One-off integration costs | B30: €m | D30: =-(IF(AND(INDEX(Inputs!$D$57:$F$57,$C$3)=1,D$7=Inputs!$D$74),Inputs!$D$80,0)+IF(AND(INDEX(Inputs!$D$58:$F$58,$C$3)=1,D$7=Inputs!$E$74),Inputs!$E$80,0)) -> 0 | E30: =-(IF(AND(INDEX(Inputs!$D$57:$F$57,$C$3)=1,E$7=Inputs!$D$74),Inputs!$D$80,0)+IF(AND(INDEX(Inputs!$D$58:$F$58,$C$3)=1,E$7=Inputs!$E$74),Inputs!$E$80,0)) -> -2.5 | F30: =-(IF(AND(INDEX(Inputs!$D$57:$F$57,$C$3)=1,F$7=Inputs!$D$74),Inputs!$D$80,0)+IF(AND(INDEX(Inputs!$D$58:$F$58,$C$3)=1,F$7=Inputs!$E$74),Inputs!$E$80,0)) -> -1.5 | G30: =-(IF(AND(INDEX(Inputs!$D$57:$F$57,$C$3)=1,G$7=Inputs!$D$74),Inputs!$D$80,0)+IF(AND(INDEX(Inputs!$D$58:$F$58,$C$3)=1,G$7=Inputs!$E$74),Inputs!$E$80,0)) -> 0 | H30: =-(IF(AND(INDEX(Inputs!$D$57:$F$57,$C$3)=1,H$7=Inputs!$D$74),Inputs!$D$80,0)+IF(AND(INDEX(Inputs!$D$58:$F$58,$C$3)=1,H$7=Inputs!$E$74),Inputs!$E$80,0)) -> 0
A31: Maintenance and placed-analyzer capex | B31: €m | D31: =-D14*Inputs!$C$63 -> -6.6 | E31: =-E14*Inputs!$C$63 -> -8.4908 | F31: =-F14*Inputs!$C$63 -> -10.186282 | G31: =-G14*Inputs!$C$63 -> -11.270882 | H31: =-H14*Inputs!$C$63 -> -12.431521
A32: Capitalised R&D | B32: €m | D32: =-D14*Inputs!$C$64 -> -2.475 | E32: =-E14*Inputs!$C$64 -> -3.18405 | F32: =-F14*Inputs!$C$64 -> -3.8198557 | G32: =-G14*Inputs!$C$64 -> -4.2265808 | H32: =-H14*Inputs!$C$64 -> -4.6618205
A33: Growth capex | B33: €m | D33: =-Inputs!D$65 -> -5 | E33: =-Inputs!E$65 -> -4 | F33: =-Inputs!F$65 -> -2 | G33: =-Inputs!G$65 -> 0 | H33: =-Inputs!H$65 -> 0
A34: Change in net working capital | B34: €m | D34: =-(D57-C57-D58) -> -3.3 | E34: =-(E57-D57-E58) -> -4.2394 | F34: =-(F57-E57-F58) -> -5.365151 | G34: =-(G57-F57-G58) -> -5.9653002 | H34: =-(H57-G57-H58) -> -6.3835165 | I34: Excludes the working capital bought with add-ons (paid for in the purchase price)
A35: Cash taxes | B35: €m | D35: =-D54 -> -6.012875 | E35: =-E54 -> -7.36593 | F35: =-F54 -> -9.6599539 | G35: =-G54 -> -11.620955 | H35: =-H54 -> -14.396023
A36: Net interest expense | B36: €m | D36: =-D86 -> -18.29875 | E36: =-E86 -> -20.580143 | F36: =-F86 -> -21.76025 | G36: =-G86 -> -22.623169 | H36: =-H86 -> -20.945792
A37: Free cash flow | B37: €m | D37: =SUM(D29:D36) -> 4.458375 | E37: =SUM(E29:E36) -> 10.464277 | F37: =SUM(F29:F36) -> 21.240891 | G37: =SUM(G29:G36) -> 30.825147 | H37: =SUM(H29:H36) -> 37.802718
A38: Earn-out paid to the vendor | B38: €m | D38: =-IF(D$7=Inputs!$C$23,$C$137,0) -> 0 | E38: =-IF(E$7=Inputs!$C$23,$C$137,0) -> 0 | F38: =-IF(F$7=Inputs!$C$23,$C$137,0) -> -40 | G38: =-IF(G$7=Inputs!$C$23,$C$137,0) -> 0 | H38: =-IF(H$7=Inputs!$C$23,$C$137,0) -> 0 | I38: Paid by the company in the payment year; reduces debt paydown
A39: Add-on acquisitions incl. deal costs | B39: €m | D39: =-(IF(AND(INDEX(Inputs!$D$57:$F$57,$C$3)=1,D$7=Inputs!$D$74),Inputs!$D$86,0)+IF(AND(INDEX(Inputs!$D$58:$F$58,$C$3)=1,D$7=Inputs!$E$74),Inputs!$E$86,0)) -> 0 | E39: =-(IF(AND(INDEX(Inputs!$D$57:$F$57,$C$3)=1,E$7=Inputs!$D$74),Inputs!$D$86,0)+IF(AND(INDEX(Inputs!$D$58:$F$58,$C$3)=1,E$7=Inputs!$E$74),Inputs!$E$86,0)) -> -50.7584 | F39: =-(IF(AND(INDEX(Inputs!$D$57:$F$57,$C$3)=1,F$7=Inputs!$D$74),Inputs!$D$86,0)+IF(AND(INDEX(Inputs!$D$58:$F$58,$C$3)=1,F$7=Inputs!$E$74),Inputs!$E$86,0)) -> -37.08 | G39: =-(IF(AND(INDEX(Inputs!$D$57:$F$57,$C$3)=1,G$7=Inputs!$D$74),Inputs!$D$86,0)+IF(AND(INDEX(Inputs!$D$58:$F$58,$C$3)=1,G$7=Inputs!$E$74),Inputs!$E$86,0)) -> 0 | H39: =-(IF(AND(INDEX(Inputs!$D$57:$F$57,$C$3)=1,H$7=Inputs!$D$74),Inputs!$D$86,0)+IF(AND(INDEX(Inputs!$D$58:$F$58,$C$3)=1,H$7=Inputs!$E$74),Inputs!$E$86,0)) -> 0
A40: Cash flow before debt movements | B40: €m | D40: =D37+D38+D39 -> 4.458375 | E40: =E37+E38+E39 -> -40.294123 | F40: =F37+F38+F39 -> -55.839109 | G40: =G37+G38+G39 -> 30.825147 | H40: =H37+H38+H39 -> 37.802718
A41: Cash conversion: (EBITDA – capex – ΔNWC) / EBITDA | B41: % | D41: =(D29+D31+D32+D33+D34)/D29 -> 0.6234695 | E41: =(E29+E31+E32+E33+E34)/E29 -> 0.67259546 | F41: =(F29+F31+F32+F33+F34)/F29 -> 0.71705793 | G41: =(G29+G31+G32+G33+G34)/G29 -> 0.75196743 | H41: =(H29+H31+H32+H33+H34)/H29 -> 0.75702215
A43: Corporate tax (French interest cap)
A44: EBITDA | B44: €m | D44: =D24 -> 46.145 | E44: =E24 -> 60.8246 | F44: =F24 -> 75.532383 | G44: =G24 -> 86.532034 | H44: =H24 -> 96.621391
A45: One-off integration costs | B45: €m | D45: =D30 -> 0 | E45: =E30 -> -2.5 | F45: =F30 -> -1.5 | G45: =G30 -> 0 | H45: =H30 -> 0
...

Sheet LBO_Down
A1: Project Lumière – LBO model: Downside case
A2: €m unless stated · financial year to December · closing 31 December 2026 · exit 31 December 2031
A3: Case index (1 = Base, 2 = Management, 3 = Downside) | C3: 3
A5: €m | B5: Unit | C5: FY2026E | D5: FY2027 | E5: FY2028 | F5: FY2029 | G5: FY2030 | H5: FY2031
A6: Years from closing | C6: 0 | D6: =C6+1 -> 1 | E6: =D6+1 -> 2 | F6: =E6+1 -> 3 | G6: =F6+1 -> 4 | H6: =G6+1 -> 5
A7: Financial year | C7: 2026 | D7: =C7+1 -> 2027 | E7: =D7+1 -> 2028 | F7: =E7+1 -> 2029 | G7: =F7+1 -> 2030 | H7: =G7+1 -> 2031
A9: Revenue
A10: Organic revenue growth | B10: % | D10: =INDEX(Inputs!D$45:D$47,$C$3)+Inputs!$C$52 -> 0.04 | E10: =INDEX(Inputs!E$45:E$47,$C$3)+Inputs!$C$52 -> 0.04 | F10: =INDEX(Inputs!F$45:F$47,$C$3)+Inputs!$C$52 -> 0.045 | G10: =INDEX(Inputs!G$45:G$47,$C$3)+Inputs!$C$52 -> 0.045 | H10: =INDEX(Inputs!H$45:H$47,$C$3)+Inputs!$C$52 -> 0.045 | I10: Inputs rows 45–47 picked by case index, plus the flex delta
A11: Organic revenue | B11: €m | C11: =Inputs!$C$5 -> 150 | D11: =C11*(1+D10) -> 156 | E11: =D11*(1+E10) -> 162.24 | F11: =E11*(1+F10) -> 169.5408 | G11: =F11*(1+G10) -> 177.17014 | H11: =G11*(1+H10) -> 185.14279
A12: Add-on A revenue (Germany) | B12: €m | C12: 0 | D12: =IF(AND(INDEX(Inputs!$D$57:$F$57,$C$3)=1,D$7>=Inputs!$D$74),Inputs!$D$75*(1+Inputs!$D$76)^(D$7-Inputs!$D$74+1),0) -> 0 | E12: =IF(AND(INDEX(Inputs!$D$57:$F$57,$C$3)=1,E$7>=Inputs!$D$74),Inputs!$D$75*(1+Inputs!$D$76)^(E$7-Inputs!$D$74+1),0) -> 0 | F12: =IF(AND(INDEX(Inputs!$D$57:$F$57,$C$3)=1,F$7>=Inputs!$D$74),Inputs!$D$75*(1+Inputs!$D$76)^(F$7-Inputs!$D$74+1),0) -> 0 | G12: =IF(AND(INDEX(Inputs!$D$57:$F$57,$C$3)=1,G$7>=Inputs!$D$74),Inputs!$D$75*(1+Inputs!$D$76)^(G$7-Inputs!$D$74+1),0) -> 0 | H12: =IF(AND(INDEX(Inputs!$D$57:$F$57,$C$3)=1,H$7>=Inputs!$D$74),Inputs!$D$75*(1+Inputs!$D$76)^(H$7-Inputs!$D$74+1),0) -> 0 | I12: Consolidated from 1 January of the acquisition year
A13: Add-on B revenue (US) | B13: €m | C13: 0 | D13: =IF(AND(INDEX(Inputs!$D$58:$F$58,$C$3)=1,D$7>=Inputs!$E$74),Inputs!$E$75*(1+Inputs!$E$76)^(D$7-Inputs!$E$74+1),0) -> 0 | E13: =IF(AND(INDEX(Inputs!$D$58:$F$58,$C$3)=1,E$7>=Inputs!$E$74),Inputs!$E$75*(1+Inputs!$E$76)^(E$7-Inputs!$E$74+1),0) -> 0 | F13: =IF(AND(INDEX(Inputs!$D$58:$F$58,$C$3)=1,F$7>=Inputs!$E$74),Inputs!$E$75*(1+Inputs!$E$76)^(F$7-Inputs!$E$74+1),0) -> 0 | G13: =IF(AND(INDEX(Inputs!$D$58:$F$58,$C$3)=1,G$7>=Inputs!$E$74),Inputs!$E$75*(1+Inputs!$E$76)^(G$7-Inputs!$E$74+1),0) -> 0 | H13: =IF(AND(INDEX(Inputs!$D$58:$F$58,$C$3)=1,H$7>=Inputs!$E$74),Inputs!$E$75*(1+Inputs!$E$76)^(H$7-Inputs!$E$74+1),0) -> 0
A14: Total revenue | B14: €m | C14: =SUM(C11:C13) -> 150 | D14: =SUM(D11:D13) -> 156 | E14: =SUM(E11:E13) -> 162.24 | F14: =SUM(F11:F13) -> 169.5408 | G14: =SUM(G11:G13) -> 177.17014 | H14: =SUM(H11:H13) -> 185.14279
A15: Total revenue growth | B15: % | D15: =D14/C14-1 -> 0.04 | E15: =E14/D14-1 -> 0.04 | F15: =F14/E14-1 -> 0.045 | G15: =G14/F14-1 -> 0.045 | H15: =H14/G14-1 -> 0.045
A17: EBITDA (ARCHIMED definition: pre-IFRS 16, fully loaded)
A18: Organic EBITDA margin | B18: % | C18: =C19/C11 -> 0.26666667 | D18: =INDEX(Inputs!D$48:D$50,$C$3)+Inputs!$C$53 -> 0.265 | E18: =INDEX(Inputs!E$48:E$50,$C$3)+Inputs!$C$53 -> 0.265 | F18: =INDEX(Inputs!F$48:F$50,$C$3)+Inputs!$C$53 -> 0.265 | G18: =INDEX(Inputs!G$48:G$50,$C$3)+Inputs!$C$53 -> 0.265 | H18: =INDEX(Inputs!H$48:H$50,$C$3)+Inputs!$C$53 -> 0.265
A19: Organic EBITDA | B19: €m | C19: =Inputs!$C$8 -> 40 | D19: =D11*D18 -> 41.34 | E19: =E11*E18 -> 42.9936 | F19: =F11*F18 -> 44.928312 | G19: =G11*G18 -> 46.950086 | H19: =H11*H18 -> 49.06284
A20: Add-on A EBITDA (standalone) | B20: €m | C20: 0 | D20: =D12*Inputs!$D$77 -> 0 | E20: =E12*Inputs!$D$77 -> 0 | F20: =F12*Inputs!$D$77 -> 0 | G20: =G12*Inputs!$D$77 -> 0 | H20: =H12*Inputs!$D$77 -> 0
A21: Add-on A cost synergies | B21: €m | C21: 0 | D21: =IF(D12>0,Inputs!$D$81*IF(D$7-Inputs!$D$74=0,Inputs!$D$82,IF(D$7-Inputs!$D$74=1,Inputs!$D$83,Inputs!$D$84)),0) -> 0 | E21: =IF(E12>0,Inputs!$D$81*IF(E$7-Inputs!$D$74=0,Inputs!$D$82,IF(E$7-Inputs!$D$74=1,Inputs!$D$83,Inputs!$D$84)),0) -> 0 | F21: =IF(F12>0,Inputs!$D$81*IF(F$7-Inputs!$D$74=0,Inputs!$D$82,IF(F$7-Inputs!$D$74=1,Inputs!$D$83,Inputs!$D$84)),0) -> 0 | G21: =IF(G12>0,Inputs!$D$81*IF(G$7-Inputs!$D$74=0,Inputs!$D$82,IF(G$7-Inputs!$D$74=1,Inputs!$D$83,Inputs!$D$84)),0) -> 0 | H21: =IF(H12>0,Inputs!$D$81*IF(H$7-Inputs!$D$74=0,Inputs!$D$82,IF(H$7-Inputs!$D$74=1,Inputs!$D$83,Inputs!$D$84)),0) -> 0
A22: Add-on B EBITDA (standalone) | B22: €m | C22: 0 | D22: =D13*Inputs!$E$77 -> 0 | E22: =E13*Inputs!$E$77 -> 0 | F22: =F13*Inputs!$E$77 -> 0 | G22: =G13*Inputs!$E$77 -> 0 | H22: =H13*Inputs!$E$77 -> 0
A23: Add-on B cost synergies | B23: €m | C23: 0 | D23: =IF(D13>0,Inputs!$E$81*IF(D$7-Inputs!$E$74=0,Inputs!$E$82,IF(D$7-Inputs!$E$74=1,Inputs!$E$83,Inputs!$E$84)),0) -> 0 | E23: =IF(E13>0,Inputs!$E$81*IF(E$7-Inputs!$E$74=0,Inputs!$E$82,IF(E$7-Inputs!$E$74=1,Inputs!$E$83,Inputs!$E$84)),0) -> 0 | F23: =IF(F13>0,Inputs!$E$81*IF(F$7-Inputs!$E$74=0,Inputs!$E$82,IF(F$7-Inputs!$E$74=1,Inputs!$E$83,Inputs!$E$84)),0) -> 0 | G23: =IF(G13>0,Inputs!$E$81*IF(G$7-Inputs!$E$74=0,Inputs!$E$82,IF(G$7-Inputs!$E$74=1,Inputs!$E$83,Inputs!$E$84)),0) -> 0 | H23: =IF(H13>0,Inputs!$E$81*IF(H$7-Inputs!$E$74=0,Inputs!$E$82,IF(H$7-Inputs!$E$74=1,Inputs!$E$83,Inputs!$E$84)),0) -> 0
A24: Total EBITDA | B24: €m | C24: =SUM(C19:C23) -> 40 | D24: =SUM(D19:D23) -> 41.34 | E24: =SUM(E19:E23) -> 42.9936 | F24: =SUM(F19:F23) -> 44.928312 | G24: =SUM(G19:G23) -> 46.950086 | H24: =SUM(H19:H23) -> 49.06284
A25: EBITDA margin | B25: % | C25: =C24/C14 -> 0.26666667 | D25: =D24/D14 -> 0.265 | E25: =E24/E14 -> 0.265 | F25: =F24/F14 -> 0.265 | G25: =G24/G14 -> 0.265 | H25: =H24/H14 -> 0.265
A26: EBITDA growth | B26: % | D26: =D24/C24-1 -> 0.0335 | E26: =E24/D24-1 -> 0.04 | F26: =F24/E24-1 -> 0.045 | G26: =G24/F24-1 -> 0.045 | H26: =H24/G24-1 -> 0.045
A28: Free cash flow
A29: EBITDA | B29: €m | D29: =D24 -> 41.34 | E29: =E24 -> 42.9936 | F29: =F24 -> 44.928312 | G29: =G24 -> 46.950086 | H29: =H24 -> 49.06284
A30: One-off integration costs | B30: €m | D30: =-(IF(AND(INDEX(Inputs!$D$57:$F$57,$C$3)=1,D$7=Inputs!$D$74),Inputs!$D$80,0)+IF(AND(INDEX(Inputs!$D$58:$F$58,$C$3)=1,D$7=Inputs!$E$74),Inputs!$E$80,0)) -> 0 | E30: =-(IF(AND(INDEX(Inputs!$D$57:$F$57,$C$3)=1,E$7=Inputs!$D$74),Inputs!$D$80,0)+IF(AND(INDEX(Inputs!$D$58:$F$58,$C$3)=1,E$7=Inputs!$E$74),Inputs!$E$80,0)) -> 0 | F30: =-(IF(AND(INDEX(Inputs!$D$57:$F$57,$C$3)=1,F$7=Inputs!$D$74),Inputs!$D$80,0)+IF(AND(INDEX(Inputs!$D$58:$F$58,$C$3)=1,F$7=Inputs!$E$74),Inputs!$E$80,0)) -> 0 | G30: =-(IF(AND(INDEX(Inputs!$D$57:$F$57,$C$3)=1,G$7=Inputs!$D$74),Inputs!$D$80,0)+IF(AND(INDEX(Inputs!$D$58:$F$58,$C$3)=1,G$7=Inputs!$E$74),Inputs!$E$80,0)) -> 0 | H30: =-(IF(AND(INDEX(Inputs!$D$57:$F$57,$C$3)=1,H$7=Inputs!$D$74),Inputs!$D$80,0)+IF(AND(INDEX(Inputs!$D$58:$F$58,$C$3)=1,H$7=Inputs!$E$74),Inputs!$E$80,0)) -> 0
A31: Maintenance and placed-analyzer capex | B31: €m | D31: =-D14*Inputs!$C$63 -> -6.24 | E31: =-E14*Inputs!$C$63 -> -6.4896 | F31: =-F14*Inputs!$C$63 -> -6.781632 | G31: =-G14*Inputs!$C$63 -> -7.0868054 | H31: =-H14*Inputs!$C$63 -> -7.4057117
A32: Capitalised R&D | B32: €m | D32: =-D14*Inputs!$C$64 -> -2.34 | E32: =-E14*Inputs!$C$64 -> -2.4336 | F32: =-F14*Inputs!$C$64 -> -2.543112 | G32: =-G14*Inputs!$C$64 -> -2.657552 | H32: =-H14*Inputs!$C$64 -> -2.7771419
A33: Growth capex | B33: €m | D33: =-Inputs!D$65 -> -5 | E33: =-Inputs!E$65 -> -4 | F33: =-Inputs!F$65 -> -2 | G33: =-Inputs!G$65 -> 0 | H33: =-Inputs!H$65 -> 0
A34: Change in net working capital | B34: €m | D34: =-(D57-C57-D58) -> -1.32 | E34: =-(E57-D57-E58) -> -1.3728 | F34: =-(F57-E57-F58) -> -1.606176 | G34: =-(G57-F57-G58) -> -1.6784539 | H34: =-(H57-G57-H58) -> -1.7539843 | I34: Excludes the working capital bought with add-ons (paid for in the purchase price)
A35: Cash taxes | B35: €m | D35: =-D54 -> -5.2845 | E35: =-E54 -> -5.49588 | F35: =-F54 -> -5.7431946 | G35: =-G54 -> -6.0016384 | H35: =-H54 -> -6.2717121
A36: Net interest expense | B36: €m | D36: =-D86 -> -18.29875 | E36: =-E86 -> -18.105919 | F36: =-F86 -> -17.761953 | G36: =-G86 -> -17.188726 | H36: =-H86 -> -16.355985
A37: Free cash flow | B37: €m | D37: =SUM(D29:D36) -> 2.85675 | E37: =SUM(E29:E36) -> 5.0958006 | F37: =SUM(F29:F36) -> 8.4922446 | G37: =SUM(G29:G36) -> 12.33691 | H37: =SUM(H29:H36) -> 14.498305
A38: Earn-out paid to the vendor | B38: €m | D38: =-IF(D$7=Inputs!$C$23,$C$137,0) -> 0 | E38: =-IF(E$7=Inputs!$C$23,$C$137,0) -> 0 | F38: =-IF(F$7=Inputs!$C$23,$C$137,0) -> 0 | G38: =-IF(G$7=Inputs!$C$23,$C$137,0) -> 0 | H38: =-IF(H$7=Inputs!$C$23,$C$137,0) -> 0 | I38: Paid by the company in the payment year; reduces debt paydown
A39: Add-on acquisitions incl. deal costs | B39: €m | D39: =-(IF(AND(INDEX(Inputs!$D$57:$F$57,$C$3)=1,D$7=Inputs!$D$74),Inputs!$D$86,0)+IF(AND(INDEX(Inputs!$D$58:$F$58,$C$3)=1,D$7=Inputs!$E$74),Inputs!$E$86,0)) -> 0 | E39: =-(IF(AND(INDEX(Inputs!$D$57:$F$57,$C$3)=1,E$7=Inputs!$D$74),Inputs!$D$86,0)+IF(AND(INDEX(Inputs!$D$58:$F$58,$C$3)=1,E$7=Inputs!$E$74),Inputs!$E$86,0)) -> 0 | F39: =-(IF(AND(INDEX(Inputs!$D$57:$F$57,$C$3)=1,F$7=Inputs!$D$74),Inputs!$D$86,0)+IF(AND(INDEX(Inputs!$D$58:$F$58,$C$3)=1,F$7=Inputs!$E$74),Inputs!$E$86,0)) -> 0 | G39: =-(IF(AND(INDEX(Inputs!$D$57:$F$57,$C$3)=1,G$7=Inputs!$D$74),Inputs!$D$86,0)+IF(AND(INDEX(Inputs!$D$58:$F$58,$C$3)=1,G$7=Inputs!$E$74),Inputs!$E$86,0)) -> 0 | H39: =-(IF(AND(INDEX(Inputs!$D$57:$F$57,$C$3)=1,H$7=Inputs!$D$74),Inputs!$D$86,0)+IF(AND(INDEX(Inputs!$D$58:$F$58,$C$3)=1,H$7=Inputs!$E$74),Inputs!$E$86,0)) -> 0
A40: Cash flow before debt movements | B40: €m | D40: =D37+D38+D39 -> 2.85675 | E40: =E37+E38+E39 -> 5.0958006 | F40: =F37+F38+F39 -> 8.4922446 | G40: =G37+G38+G39 -> 12.33691 | H40: =H37+H38+H39 -> 14.498305
A41: Cash conversion: (EBITDA – capex – ΔNWC) / EBITDA | B41: % | D41: =(D29+D31+D32+D33+D34)/D29 -> 0.63957426 | E41: =(E29+E31+E32+E33+E34)/E29 -> 0.66748539 | F41: =(F29+F31+F32+F33+F34)/F29 -> 0.71218772 | G41: =(G29+G31+G32+G33+G34)/G29 -> 0.75670308 | H41: =(H29+H31+H32+H33+H34)/H29 -> 0.75670308
A43: Corporate tax (French interest cap)
A44: EBITDA | B44: €m | D44: =D24 -> 41.34 | E44: =E24 -> 42.9936 | F44: =F24 -> 44.928312 | G44: =G24 -> 46.950086 | H44: =H24 -> 49.06284
A45: One-off integration costs | B45: €m | D45: =D30 -> 0 | E45: =E30 -> 0 | F45: =F30 -> 0 | G45: =G30 -> 0 | H45: =H30 -> 0
...

Sheet Returns
A1: Project Lumière – returns summary and sensitivities
A2: Investor returns = gross to the equity strip, after the management MIP, before fund fees and carry. €m unless stated.
A4: 1. Returns by case (exit at the end of FY2031)
A5: Metric | B5: Unit | C5: Base | D5: Management | E5: Downside
A6: FY2031 revenue | B6: €m | C6: =LBO_Base!H14 -> 279.45958 | D6: =LBO_Mgmt!H14 -> 310.78803 | E6: =LBO_Down!H14 -> 185.14279
A7: FY2031 EBITDA | B7: €m | C7: =LBO_Base!H24 -> 82.759838 | D7: =LBO_Mgmt!H24 -> 96.621391 | E7: =LBO_Down!H24 -> 49.06284
A8: FY2031 EBITDA margin | B8: % | C8: =LBO_Base!H25 -> 0.29614243 | D8: =LBO_Mgmt!H25 -> 0.31089161 | E8: =LBO_Down!H25 -> 0.265
A9: EBITDA CAGR FY2026E–FY2031 (incl. add-ons) | B9: % | C9: =(LBO_Base!H24/LBO_Base!C24)^(1/5)-1 -> 0.15651675 | D9: =(LBO_Mgmt!H24/LBO_Mgmt!C24)^(1/5)-1 -> 0.19289621 | E9: =(LBO_Down!H24/LBO_Down!C24)^(1/5)-1 -> 0.041690104
A10: Exit EV / EBITDA | B10: x | C10: =LBO_Base!C98 -> 13.5 | D10: =LBO_Mgmt!C98 -> 13.5 | E10: =LBO_Down!C98 -> 12
A11: Exit enterprise value | B11: €m | C11: =LBO_Base!C99 -> 1117.2578 | D11: =LBO_Mgmt!C99 -> 1304.3888 | E11: =LBO_Down!C99 -> 588.75408
A12: Net debt at exit | B12: €m | C12: =-LBO_Base!C101 -> 230.1109 | D12: =-LBO_Mgmt!C101 -> 253.04699 | E12: =-LBO_Down!C101 -> 186.71999
A13: Exit equity value (100%) | B13: €m | C13: =LBO_Base!C102 -> 870.38804 | D13: =LBO_Mgmt!C102 -> 1031.776 | E13: =LBO_Down!C102 -> 393.20278
A14: MIP payout to management | B14: €m | C14: =-LBO_Base!C105 -> 54.218804 | D14: =-LBO_Mgmt!C105 -> 70.357596 | E14: =-LBO_Down!C105 -> 6.5002778
A15: Exit equity to investors | B15: €m | C15: =LBO_Base!C106 -> 816.16924 | D15: =LBO_Mgmt!C106 -> 961.41836 | E15: =LBO_Down!C106 -> 386.7025
A16: Equity invested at closing | B16: €m | C16: =LBO_Base!C103 -> 328.2 | D16: =LBO_Mgmt!C103 -> 328.2 | E16: =LBO_Down!C103 -> 328.2
A17: MOIC | B17: x | C17: =LBO_Base!C107 -> 2.4868045 | D17: =LBO_Mgmt!C107 -> 2.9293673 | E17: =LBO_Down!C107 -> 1.1782526
A18: IRR | B18: % | C18: =LBO_Base!C109 -> 0.19985379 | D18: =LBO_Mgmt!C109 -> 0.23980895 | E18: =LBO_Down!C109 -> 0.033350564
A19: Earn-out paid to vendor | B19: €m | C19: =-LBO_Base!C128 -> 0 | D19: =-LBO_Mgmt!C128 -> 40 | E19: =-LBO_Down!C128 -> 0
A20: Add-ons acquired (price incl. costs) | B20: €m | C20: =-LBO_Base!C127 -> 87.8384 | D20: =-LBO_Mgmt!C127 -> 87.8384 | E20: =-LBO_Down!C127 -> 0
A21: Peak net leverage, FY2027–FY2031 | B21: x | C21: =MAX(LBO_Base!D91:H91) -> 5.0975229 | D21: =MAX(LBO_Mgmt!D91:H91) -> 4.887672 | E21: =MAX(LBO_Down!D91:H91) -> 5.494515
A22: Lowest EBITDA / net interest | B22: x | C22: =MIN(LBO_Base!D92:H92) -> 2.4233213 | D22: =MIN(LBO_Mgmt!D92:H92) -> 2.521757 | E22: =MIN(LBO_Down!D92:H92) -> 2.2591707
A23: Lowest covenant headroom | B23: % | C23: =MIN(LBO_Base!D93:H93) -> 0.38211844 | D23: =MIN(LBO_Mgmt!D93:H93) -> 0.40755491 | E23: =MIN(LBO_Down!D93:H93) -> 0.33399818
A24: ARCHIMED equity invested | B24: €m | C24: =Transaction!$C$15 -> 282.2 | D24: =Transaction!$C$15 -> 282.2 | E24: =Transaction!$C$15 -> 282.2
A25: ARCHIMED exit proceeds | B25: €m | C25: =C15*Transaction!$D$21 -> 701.77623 | D25: =D15*Transaction!$D$21 -> 826.66747 | E25: =E15*Transaction!$D$21 -> 332.50288
A26: ARCHIMED capital gain | B26: €m | C26: =C25-C24 -> 419.57623 | D26: =D25-D24 -> 544.46747 | E26: =E25-E24 -> 50.302881
A28: 2. Equity value bridge – Base case
A29: Step | B29: Unit | C29: €m | D29: % of gain
A30: Equity invested at closing | B30: €m | C30: =LBO_Base!C123 -> 328.2
A31: Organic EBITDA growth × entry multiple | B31: €m | C31: =LBO_Base!C124 -> 380.64287 | D31: =C31/($C$40-$C$30) -> 0.78005506
A32: Add-on EBITDA incl. synergies × entry multiple | B32: €m | C32: =LBO_Base!C125 -> 196.61494 | D32: =C32/($C$40-$C$30) -> 0.40292486
A33: Exit vs. entry multiple | B33: €m | C33: =LBO_Base!C126 -> 0 | D33: =C33/($C$40-$C$30) -> 0
A34: Add-on purchase prices (debt-funded) | B34: €m | C34: =LBO_Base!C127 -> -87.8384 | D34: =C34/($C$40-$C$30) -> -0.18000807
A35: Earn-out paid | B35: €m | C35: =LBO_Base!C128 -> 0 | D35: =C35/($C$40-$C$30) -> 0
A36: Cumulative free cash flow (debt paydown) | B36: €m | C36: =LBO_Base!C129 -> 87.727498 | D36: =C36/($C$40-$C$30) -> 0.1797808
A37: Transaction and financing fees | B37: €m | C37: =LBO_Base!C130 -> -18.2 | D37: =C37/($C$40-$C$30) -> -0.037297433
A38: Exit costs | B38: €m | C38: =LBO_Base!C131 -> -16.758867 | D38: =C38/($C$40-$C$30) -> -0.034344106
A39: MIP payout | B39: €m | C39: =LBO_Base!C132 -> -54.218804 | D39: =C39/($C$40-$C$30) -> -0.11111111
A40: Exit equity to investors | B40: €m | C40: =LBO_Base!C133 -> 816.16924
A42: 3. Bid ladder – returns by entry price (each case at its own exit multiple)
A43: Price point (€m) | B43: Entry EV | C43: x UW EBITDA | D43: x vendor EBITDA | E43: Equity in | F43: Base IRR | G43: Base MOIC | H43: Mgmt IRR | I43: Mgmt MOIC | J43: Down IRR | K43: Down MOIC
...
